Workbook

Sheet README
A1: Supplementary Table S1 - Register of the review corpus (126 studies)
A2: Connecting Social Media Analysis and Financial Market Events: A Systematic Survey
A4: What this file is
A5: A study-level register of the 126 works included in the final synthesis. Each record is linked to its PRISMA category (Figure: PRISMA flow diagram), the manuscript section in which it is analysed and, where applicable, its methodological class (C1-C6, F1-F5) and appendix table.
A6: The register was compiled from the final manuscript and its bibliographic database on 18 October 2026 and synchronised with the revised manuscript on 19 October 2026 (all 146 cited keys: 126 in the corpus, 20 on not_in_corpus); bibliographic data are taken from surveybib_corrected.bib. Scripts and data files are described in the README.md of the accompanying repository.
A8: How the corpus was checked
A9: Every PRISMA category count is recomputed from the Data sheet (sheet PRISMA_check) and matches the flow diagram: social media analysis 59, financial market events 40, cross-domain events and causality 27 (total 126). Publication types are recomputed on the Counts sheet and match the corpus-composition table (103 journal articles, 7 conference papers, 3 books, 2 book chapters, 11 preprints/working papers).
A11: Metadata check
A12: On 19 October 2026 the bibliographic metadata of all 126 studies were checked against OpenAlex and their DOIs against Crossref (verify_corpus.py); corrections to the bibliographic database are listed on sheet bib_corrections.
A14: Retrospective known-item retrieval check (supplementary; sheets search_protocol, validation_result, validation_terms, protocol_history, openalex_fields)
A15: One protocol (search_protocol), following the objective approach of Hausner et al. (2012, Systematic Reviews 1:19). The 82 included studies published 2021-2026 were split at random within each flow-diagram category (seed 20261019) into a development set (44) and a validation set (38). Candidate terms were taken from the development titles only (words and two-word phrases in at least two titles) and from the keywords of Table 2; terms over-represented in the development titles relative to OpenAlex were kept, with the threshold chosen on the development set (R = 100), giving a title query of 27 terms (frozen, SHA-256 recorded). Restrictions: publication dates 2020-2026, ineligible document types excluded, OpenAlex subject fields of the development studies; no language restriction.
A16: Result (20 October 2026): 311,556 records (528,902 without the subject-field restriction on the same day; -41.1%); validation set 29 of 38 studies retrieved (76.3%, 95% CI 60.8-87.0%), 29 of the 36 indexed in OpenAlex (80.6%, 95% CI 65.0-90.2%); development set 42 of 44. The subject-field restriction was chosen after the fields of the validation studies had been inspected, so it is not independently validated; it did not remove any of the known included studies retrieved by the original query. The final configuration is used for the reported filtered retrieval result, while the original pre-specified configuration and all intermediate runs are retained as part of the methodological audit trail. The original configuration, a language filter that lost two studies without an assigned language, and rejected phrase-based variants are on sheet protocol_history. The check measures retrieval of known included studies; because both samples come from the included corpus, it cannot establish the completeness or sensitivity of the original search. Per-study results: Data, columns validation_set and retrieved_by_final_query.
... A19: Data - one row per included study. | not_in_corpus - 20 works cited in the manuscript only for background or methodological guidance. | codebook - definition of every column and label. | class_definitions - definitions of classes C1-C6 and F1-F5 quoted from the manuscript, with the assignment procedure and counts (formulas). | Counts - publication types, themes and classes (formulas). | PRISMA_check - diagram vs register (formulas). | search_concepts_table2 - search concepts and Boolean strings as reported in the manuscript. | search_protocol - protocol of the known-item retrieval check. | validation_result - filters, frozen query, threshold, records, retrieval in the development and validation sets, per-study result. | validation_terms - candidate terms with OpenAlex counts and over-representation ratios. | protocol_history - methodological audit trail: all configurations run (original pre-specified, intermediate, dropped, rejected and final), with records and retrieval; records by OpenAlex field. | openalex_fields - OpenAlex field, subfield and primary topic of the 82 studies published 2021-2026. | bib_corrections - corrections applied to surveybib.bib. | decisions_log - decisions taken when compiling the register.

Sheet Data
A1: study_id | B1: bibkey | C1: authors | D1: year | E1: title | F1: venue | G1: publication_type | H1: doi | I1: theme | J1: prisma_box | K1: xref_to | L1: section_no | M1: section | N1: method_class | O1: appendix_table | P1: cited_in | Q1: study_role | R1: revision_status | S1: metadata_check | T1: note | U1: openalex_id | V1: in_search_window | W1: validation_set | X1: retrieved_by_final_query
A2: S001 | B2: vandenbos2007apa | C2: VandenBos, Gary R. | D2: 2007 | E2: APA Dictionary of Psychology | F2: American Psychological Association | G2: Book | I2: Social media analysis | J2: Opinion in Social Networks | L2: 3.2 | M2: How Opinion Is Defined | P2: 3.2 How Opinion Is Defined | Q2: Foundational | S2: OpenAlex W1700102289 (matched by title); no DOI in .bib | U2: W1700102289 | V2: no
A3: S002 | B3: musch2003psychology | C3: Musch, Jochen; Klauer, Karl C | D3: 2003 | E3: The psychology of evaluation: Affective processes in cognition and emotion | F3: Psychology Press | G3: Book | I3: Social media analysis | J3: Opinion in Social Networks | L3: 3.2 | M3: How Opinion Is Defined | P3: 3.2 How Opinion Is Defined | Q3: Foundational | S3: Not indexed in OpenAlex | V3: no
A4: S003 | B4: zhang4450056integrated | C4: Zhang, Xiaoming John; Zhang, Ping | D4: 2023 | E4: An Integrated Mathematical Framework for Opinion Dynamics | F4: Available at SSRN | G4: Preprint / working paper | H4: 10.2139/ssrn.4450056 | I4: Social media analysis | J4: Opinion in Social Networks | L4: 3.2 | M4: How Opinion Is Defined | P4: 3.2 How Opinion Is Defined | Q4: Foundational | S4: OpenAlex W4376855031; Crossref DOI record checked | U4: W4376855031 | V4: yes | W4: development
A5: S004 | B5: degroot1974reaching | C5: DeGroot, Morris H | D5: 1974 | E5: Reaching a consensus | F5: Journal of the American Statistical association | G5: Journal article | H5: 10.1080/01621459.1974.10480137 | I5: Social media analysis | J5: Opinion in Social Networks | L5: 3.2 | M5: How Opinion Is Defined | P5: 3.2 How Opinion Is Defined | Q5: Foundational | S5: OpenAlex W1998692453; Crossref DOI record checked | U5: W1998692453 | V5: no
A6: S005 | B6: hegselmann2002opinion | C6: Hegselmann, Rainer; Krause, Ulrich | D6: 2002 | E6: Opinion dynamics and bounded confidence: models, analysis and simulation | F6: Journal of Artificial Societies and Social Simulation | G6: Journal article | I6: Social media analysis | J6: Opinion in Social Networks | L6: 3.2 | M6: How Opinion Is Defined | P6: 3.2 How Opinion Is Defined | Q6: Foundational | S6: OpenAlex W2113096089 (matched by title); no DOI in .bib | T6: Corrected in surveybib_corrected.bib (2026-10-19): journal: Typo in journal name | U6: W2113096089 | V6: no
A7: S006 | B7: friedkin1990social | C7: Friedkin, Noah E; Johnsen, Eugene C | D7: 1990 | E7: Social influence and opinions | F7: Journal of mathematical sociology | G7: Journal article | H7: 10.1080/0022250X.1990.9990069 | I7: Social media analysis | J7: Opinion in Social Networks | L7: 3.2 | M7: How Opinion Is Defined | P7: 3.2 How Opinion Is Defined | Q7: Foundational | S7: OpenAlex W2027514326; Crossref DOI record checked | U7: W2027514326 | V7: no
A8: S007 | B8: acemoglu2011opinion | C8: Acemoglu, Daron; Ozdaglar, Asuman | D8: 2011 | E8: Opinion dynamics and learning in social networks | F8: Dynamic Games and Applications | G8: Journal article | H8: 10.1007/s13235-010-0004-1 | I8: Social media analysis | J8: Opinion in Social Networks | L8: 3.2 | M8: How Opinion Is Defined | P8: 3.2 How Opinion Is Defined | Q8: Foundational | S8: OpenAlex W3122266916; Crossref DOI record checked | U8: W3122266916 | V8: no
A9: S008 | B9: gaillard2021countering | C9: Gaillard, Stefan; Oláh, Zoril A; Venmans, Stephan; Burke, Michael | D9: 2021 | E9: Countering the cognitive, linguistic, and psychological underpinnings behind susceptibility to fake news: A review of current literature with special focus on the role of age and digital literacy | F9: Frontiers in Communication | G9: Journal article | H9: 10.3389/fcomm.2021.661801 | I9: Social media analysis | J9: Opinion in Social Networks | L9: 3.2 | M9: How Opinion Is Defined | P9: 3.2 How Opinion Is Defined | Q9: Core | S9: OpenAlex W3182204087; Crossref DOI record checked | U9: W3182204087 | V9: yes | W9: validation | X9: yes
A10: S009 | B10: kietzmann2011social | C10: Kietzmann, Jan H; Hermkens, Kristopher; McCarthy, Ian P; Silvestre, Bruno S | D10: 2011 | E10: Social media? Get serious! Understanding the functional building blocks of social media | F10: Business horizons | G10: Journal article | H10: 10.1016/j.bushor.2011.01.005 | I10: Social media analysis | J10: Opinion in Social Networks | L10: 3.2 | M10: How Opinion Is Defined | P10: 3.2 How Opinion Is Defined | Q10: Foundational | S10: OpenAlex W2093425966; Crossref DOI record checked | U10: W2093425966 | V10: no
A11: S010 | B11: ienca2023artificial | C11: Ienca, Marcello | D11: 2023 | E11: On artificial intelligence and manipulation | F11: Topoi | G11: Journal article | H11: 10.1007/s11245-023-09940-3 | I11: Social media analysis | J11: Opinion Manipulation: Definition and Typologies | L11: 3.3 | M11: Opinion Manipulation and Typology | P11: 3.3 Opinion Manipulation and Typology | Q11: Core | S11: OpenAlex W4381430332 (matched by title); DOI corrected in .bib | T11: Corrected in surveybib_corrected.bib (2026-10-19): doi: DOI not registered in Crossref; DOI of the matching OpenAlex record | U11: W4381430332 | V11: yes | W11: validation | X11: yes
A12: S011 | B12: cayuela2025influence | C12: Cayuela Tudela, Alejandro David; Pastor-Galindo, Javier; Nespoli, Pantaleone; Ruipérez-Valiente, José A. | D12: 2025 | E12: The influence operation ontology (IOO) | F12: arXiv preprint arXiv:2503.07304 | G12: Preprint / working paper | H12: 10.48550/arXiv.2503.07304 | I12: Social media analysis | J12: Opinion Manipulation: Definition and Typologies | L12: 3.3 | M12: Opinion Manipulation and Typology | P12: 3.3 Opinion Manipulation and Typology | Q12: Core | S12: Not indexed in OpenAlex | T12: arXiv preprint; not indexed in OpenAlex. | V12: yes | W12: validation | X12: not indexed in OpenAlex
A13: S012 | B13: chang2022systematic | C13: Chang, Hao-Tien; Tsai, Fu-Ching | D13: 2022 | E13: A systematic review of Internet public opinion manipulation | F13: Procedia Computer Science | G13: Journal article | H13: 10.1016/j.procs.2022.09.373 | I13: Social media analysis | J13: Opinion Manipulation: Definition and Typologies | L13: 3.3 | M13: Opinion Manipulation and Typology | P13: 3.3 Opinion Manipulation and Typology | Q13: Core | S13: OpenAlex W4312651142 (matched by title); DOI corrected in .bib | T13: Corrected in surveybib_corrected.bib (2026-10-19): doi: DOI resolved to another article (A reverse personnel assignment method ...) | U13: W4312651142 | V13: yes | W13: development
A14: S013 | B14: pastor2025influence | C14: Pastor-Galindo, Javier; Nespoli, Pantaleone; Ruipérez-Valiente, José A; Camacho, David | D14: 2025 | E14: Influence operations in social networks | F14: arXiv preprint arXiv:2502.11827 | G14: Preprint / working paper | H14: 10.48550/arXiv.2502.11827 | I14: Social media analysis | J14: Opinion Manipulation: Definition and Typologies | L14: 3.3 | M14: Opinion Manipulation and Typology | P14: 3.3 Opinion Manipulation and Typology | Q14: Core | S14: OpenAlex W4407719590; arXiv DOI (registered with DataCite, not Crossref) | T14: Cited as arXiv preprint; OpenAlex lists a published version (IEEE Internet Computing, DOI 10.1109/MIC.2026.3700710). Optional update; would change publication-type counts. | U14: W4407719590 | V14: yes | W14: development
A15: S014 | B15: pal2025media | C15: Pal, Mayuree; Rashmi, CP | D15: 2025 | E15: Media Manipulation and Disinformation: The Role of AI in Fake News Creation and Its Impact on Trust in Media | F15: Digital Citizenship and Building a Responsible Online Presence | G15: Journal article | H15: 10.4018/979-8-3693-6675-2.ch013 | I15: Social media analysis | J15: Opinion Manipulation: Definition and Typologies | L15: 3.3 | M15: Opinion Manipulation and Typology | P15: 3.3 Opinion Manipulation and Typology | Q15: Core | S15: OpenAlex W4408684161; Crossref DOI record checked | T15: Book chapter recorded as @article in .bib. | U15: W4408684161 | V15: yes | W15: development
A16: S015 | B16: kumarsocial | C16: Kumar, Pramod | D16: 2025 | E16: Social Media Manipulation: A Strategic Tool in Contemporary Information Warfare | F16: New Man International Journal of Multidisciplinary Studies (NMIJMS) | G16: Journal article | I16: Social media analysis | J16: Opinion Manipulation: Definition and Typologies | L16: 3.3 | M16: Opinion Manipulation and Typology | P16: 3.3 Opinion Manipulation and Typology | Q16: Core | S16: Not indexed in OpenAlex | T16: Weak record: no volume, issue, pages or DOI; not indexed in OpenAlex. | V16: yes | W16: validation | X16: not indexed in OpenAlex
A17: S016 | B17: paul2023mathematical | C17: Paul, Arindam Kumar; Biswas, Md Haider Ali | D17: 2023 | E17: A Mathematical Theory for Studying and Controlling the Disinformation System Dynamics | F17: International Conference on Mathematical Analysis and Application in Modeling | G17: Conference paper | H17: 10.48550/arXiv.2401.05078 | I17: Social media analysis | J17: Class 1 - Mathematical and System-Dynamics Modelling | L17: 3.4 | M17: Opinion Detection and Modeling (C1) | N17: C1 | O17: Table C1 | P17: 3.4 Opinion Detection and Modeling; Appendix A.1 | Q17: Core | S17: OpenAlex W4407057928; arXiv DOI (registered with DataCite, not Crossref) | T17: Cited with the arXiv DOI; OpenAlex lists the published chapter (DOI 10.1007/978-981-97-9194-1_20). Optional update. | U17: W4407057928 | V17: yes | W17: development
A18: S017 | B18: ge2024novel | C18: Ge, Qing; Huang, Chen; Xu, Huiling; Zhang, Jun; Wang, Haixia | D18: 2024 | E18: A Novel SIR Model-Based Public Opinion Propagation and Optimal Control | F18: 2024 China Automation Congress (CAC) | G18: Conference paper | H18: 10.1109/CAC63892.2024.10865290 | I18: Social media analysis | J18: Class 1 - Mathematical and System-Dynamics Modelling | L18: 3.4 | M18: Opinion Detection and Modeling (C1) | N18: C1 | O18: Table C1 | P18: 3.4 Opinion Detection and Modeling; Appendix A.1 | Q18: Core | S18: OpenAlex W4407432899; Crossref DOI record checked | U18: W4407432899 | V18: yes | W18: development
A19: S018 | B19: evangelatos2025modeling | C19: Evangelatos, Spyridon; Veroni, Eleni; Efthymiou, Vasilis; Nikolopoulos, Christos | D19: 2025 | E19: Modeling disinformation spread in social networks: Phase transitions and mean-field analysis | F19: ACM Transactions on the Web | G19: Journal article | H19: 10.1145/3747287 | I19: Social media analysis | J19: Class 1 - Mathematical and System-Dynamics Modelling | L19: 3.4 | M19: Opinion Detection and Modeling (C1) | N19: C1 | O19: Table C1 | P19: 3.4 Opinion Detection and Modeling; Appendix A.1 | Q19: Core | S19: OpenAlex W4412593918; Crossref DOI record checked | U19: W4412593918 | V19: yes | W19: validation | X19: yes
A20: S019 | B20: zhou2020two | C20: Zhou, Qinyue; Wu, Zhibin; Altalhi, Abdulrahman H; Herrera, Francisco | D20: 2020 | E20: A two-step communication opinion dynamics model with self-persistence and influence index for social networks based on the degroot model | F20: Information Sciences | G20: Journal article | H20: 10.1016/j.ins.2020.01.052 | I20: Social media analysis | J20: Class 1 - Mathematical and System-Dynamics Modelling | L20: 3.4 | M20: Opinion Detection and Modeling (C1) | N20: C1 | O20: Table C1 | P20: 3.4 Opinion Detection and Modeling; Appendix A.1 | Q20: Core | S20: OpenAlex W3004050991 (matched by title); DOI corrected in .bib | T20: Corrected in surveybib_corrected.bib (2026-10-19): doi: DOI resolved to another article (Recognizing novel patterns via adversarial learning ...) | U20: W3004050991 | V20: no
A21: S020 | B21: butts2023mathematical | C21: Butts, David J; Bollman, Sam A; Murillo, Michael S | D21: 2023 | E21: Mathematical modeling of disinformation and effectiveness of mitigation policies | F21: Scientific Reports | G21: Journal article | H21: 10.1038/s41598-023-45710-2 | I21: Social media analysis | J21: Class 1 - Mathematical and System-Dynamics Modelling | L21: 3.4 | M21: Opinion Detection and Modeling (C1) | N21: C1 | O21: Table C1 | P21: 3.4 Opinion Detection and Modeling; Appendix A.1 | Q21: Core | S21: OpenAlex W4388048121 (matched by title); DOI corrected in .bib | T21: Corrected in surveybib_corrected.bib (2026-10-19): doi: DOI not registered in Crossref; DOI of the matching OpenAlex record | U21: W4388048121 | V21: yes | W21: development
A22: S021 | B22: bhalla2025local | C22: Bhalla, Nikita; Lechowicz, Adam; Musco, Cameron | D22: 2025 | E22: Local edge dynamics and opinion polarization | F22: ACM Transactions on Intelligent Systems and Technology | G22: Journal article | H22: 10.1145/3709006 | I22: Social media analysis | J22: Class 1 - Mathematical and System-Dynamics Modelling | L22: 3.4 | M22: Opinion Detection and Modeling (C1) | N22: C1 | O22: Table C1 | P22: 3.4 Opinion Detection and Modeling; Appendix A.1 | Q22: Core | S22: OpenAlex W3216173699; Crossref DOI record checked | U22: W3216173699 | V22: yes | W22: validation | X22: yes
A23: S022 | B23: mridha2021comprehensive | C23: Mridha, Muhammad Firoz; Keya, Ashfia Jannat; Hamid, Md Abdul; Monowar, Muhammad Mostafa; Rahman, Md Saifur | D23: 2021 | E23: A comprehensive review on fake news detection with deep learning | F23: IEEE access | G23: Journal article | H23: 10.1109/ACCESS.2021.3129329 | I23: Social media analysis | J23: Class 2 - Machine & Deep Learning Content Detection | L23: 3.4 | M23: Opinion Detection and Modeling (C2) | N23: C2 | O23: Table C2 | P23: 3.4 Opinion Detection and Modeling; Appendix A.1 | Q23: Core | S23: OpenAlex W3216370178 (matched by title); DOI corrected in .bib | T23: Corrected in surveybib_corrected.bib (2026-10-19): doi: DOI resolved to another article (Incremental Attribute Reduction ...) | U23: W3216370178 | V23: yes | W23: validation | X23: yes
A24: S023 | B24: saadi2025enhancing | C24: Saadi, Abdelhalim; Belhadef, Hacene; Guessas, Akram; Hafirassou, Oussama | D24: 2025 | E24: Enhancing Fake News Detection with Transformer Models and Summarization | F24: Engineering, Technology & Applied Science Research | G24: Journal article | H24: 10.48084/etasr.10678 | I24: Social media analysis | J24: Class 2 - Machine & Deep Learning Content Detection | L24: 3.4 | M24: Opinion Detection and Modeling (C2) | N24: C2 | O24: Table C2 | P24: 3.4 Opinion Detection and Modeling; Appendix A.1 | Q24: Core | S24: OpenAlex W4411122931; Crossref DOI record checked | U24: W4411122931 | V24: yes | W24: validation | X24: yes
A25: S024 | B25: huang2025hybrid | C25: Huang, Tianyi; Xu, Zeqiu; Yu, Peiyang; Yi, Jingyuan; Xu, Xiaochuan | D25: 2025 | E25: A hybrid transformer model for fake news detection: Leveraging Bayesian optimization and bidirectional recurrent unit | F25: arXiv preprint arXiv:2502.09097 | G25: Preprint / working paper | H25: 10.1109/ISBDAS64762.2025.11117058 | I25: Social media analysis | J25: Class 2 - Machine & Deep Learning Content Detection | L25: 3.4 | M25: Opinion Detection and Modeling (C2) | N25: C2 | O25: Table C2 | P25: 3.4 Opinion Detection and Modeling; Appendix A.1 | Q25: Core | S25: OpenAlex W4413394554; Crossref DOI record checked | T25: Recorded as arXiv preprint; DOI is the published IEEE conference version. | U25: W4413394554 | V25: yes | W25: validation | X25: yes
A26: S025 | B26: tufchi2024transvae | C26: Tufchi, Shivani; Ahmed, Tanveer; Yadav, Ashima; Agrawal, Krishna Kant; Vidyarthi, Ankit | D26: 2024 | E26: TransVAE-PAM: A combined transformer and DAG-based approach for enhanced fake news detection in the Indian context | F26: ACM Transactions on Asian and Low-Resource Language Information Processing | G26: Journal article | H26: 10.1145/3651160 | I26: Social media analysis | J26: Class 2 - Machine & Deep Learning Content Detection | L26: 3.4 | M26: Opinion Detection and Modeling (C2) | N26: C2 | O26: Table C2 | P26: 3.4 Opinion Detection and Modeling; Appendix A.1 | Q26: Core | S26: OpenAlex W4392347598; Crossref DOI record checked | U26: W4392347598 | V26: yes | W26: development
A27: S026 | B27: sharma2025novel | C27: Sharma, Prateema; Al-Dayyeni, Wisam; Nagpal, Tapsi; Rana, Arun; Purohit, Rahul; Elaraby, Ahmed | D27: 2025 | E27: A Novel Hybrid Algorithm for Fake News Detection | F27: Digital Threats: Research and Practice | G27: Journal article | H27: 10.1145/3728473 | I27: Social media analysis | J27: Class 2 - Machine & Deep Learning Content Detection | L27: 3.4 | M27: Opinion Detection and Modeling (C2) | N27: C2 | O27: Table C2 | P27: 3.4 Opinion Detection and Modeling; Appendix A.1 | Q27: Core | S27: OpenAlex W4409256702; Crossref DOI record checked | U27: W4409256702 | V27: yes | W27: validation | X27: yes
A28: S027 | B28: ozcelik2025detecting | C28: Ozcelik, Oguzhan; Toraman, Cagri; Can, Fazli | D28: 2025 | E28: Detecting misinformation on social media using community insights and contrastive learning | F28: ACM Transactions on Intelligent Systems and Technology | G28: Journal article | H28: 10.1145/3709009 | I28: Social media analysis | J28: Class 2 - Machine & Deep Learning Content Detection | L28: 3.4 | M28: Opinion Detection and Modeling (C2) | N28: C2 | O28: Table C2 | P28: 3.4 Opinion Detection and Modeling; Appendix A.1 | Q28: Core | S28: OpenAlex W4405566696; Crossref DOI record checked | U28: W4405566696 | V28: yes | W28: development
A29: S028 | B29: yang2025llm | C29: Yang, Ruichao; Ma, Jing; Gao, Wei; Lin, Hongzhan | D29: 2025 | E29: LLM-enhanced multiple instance learning for joint rumor and stance detection with social context information | F29: ACM Transactions on Intelligent Systems and Technology | G29: Journal article | H29: 10.1145/3716856 | I29: Social media analysis | J29: Class 2 - Machine & Deep Learning Content Detection | L29: 3.4 | M29: Opinion Detection and Modeling (C2) | N29: C2 | O29: Table C2 | P29: 3.4 Opinion Detection and Modeling; Appendix A.1 | Q29: Core | S29: OpenAlex W4407369317; Crossref DOI record checked | U29: W4407369317 | V29: yes | W29: development
A30: S029 | B30: mahmud2026detecting | C30: Mahmud, Tanjim; Rahman, Md Akash; Devnath, Rimon Kanthi; Hossain, Mohammad Shahadat; Andersson, Karl | D30: 2026 | E30: Detecting Fake News in Bangla Using Linguistic and Psychological Features | F30: ACM Transactions on Social Computing | G30: Journal article | H30: 10.1145/3798302 | I30: Social media analysis | J30: Class 2 - Machine & Deep Learning Content Detection | L30: 3.4 | M30: Opinion Detection and Modeling (C2) | N30: C2 | O30: Table C2 | P30: 3.4 Opinion Detection and Modeling; Appendix A.1 | Q30: Core | S30: OpenAlex W7130827924; Crossref DOI record checked | U30: W7130827924 | V30: yes | W30: development
A31: S030 | B31: sahitaj2025hybrid | C31: Sahitaj, Ariana; Sahitaj, Premtim; Solopova, Veronika; Li, Jiaao; Möller, Sebastian; Schmitt, Vera | D31: 2025 | E31: Hybrid Annotation for Propaganda Detection: Integrating LLM Pre-Annotations with Human Intelligence | F31: arXiv preprint arXiv:2507.18343 | G31: Preprint / working paper | H31: 10.18653/v1/2025.nlp4pi-1.18 | I31: Social media analysis | J31: Class 3 - Hybrid Human-AI Annotation and Verification | L31: 3.4 | M31: Opinion Detection and Modeling (C3) | N31: C3 | O31: Table C3 | P31: 3.4 Opinion Detection and Modeling; Appendix A.1 | Q31: Core | S31: OpenAlex W4412944267; Crossref DOI record checked | T31: Recorded as arXiv preprint; DOI is the published workshop version. | U31: W4412944267 | V31: yes | W31: development
A32: S031 | B32: fan2026skeptik | C32: Fan, Arlen; Lei, Fan; Corman, Steven R; Maciejewski, Ross | D32: 2026 | E32: Skeptik: A Hybrid Framework for Combating Potential Misinformation in Journalism | F32: ACM Transactions on Interactive Intelligent Systems | G32: Journal article | H32: 10.1145/3766891 | I32: Social media analysis | J32: Class 3 - Hybrid Human-AI Annotation and Verification | L32: 3.4 | M32: Opinion Detection and Modeling (C3) | N32: C3 | O32: Table C3 | P32: 3.4 Opinion Detection and Modeling; Appendix A.1 | Q32: Core | S32: OpenAlex W4414476222; Crossref DOI record checked | U32: W4414476222 | V32: yes | W32: development
A33: S032 | B33: liu2024exploring | C33: Liu, Houjiang; Gwizdka, Jacek; Lease, Matthew | D33: 2024 | E33: Exploring Multidimensional Checkworthiness: Designing AI-assisted Claim Prioritization for Human Fact-checkers | F33: arXiv preprint arXiv:2412.08185 | G33: Preprint / working paper | H33: 10.1145/3757473 | I33: Social media analysis | J33: Class 3 - Hybrid Human-AI Annotation and Verification | L33: 3.4 | M33: Opinion Detection and Modeling (C3) | N33: C3 | O33: Table C3 | P33: 3.4 Opinion Detection and Modeling; Appendix A.1 | Q33: Core | S33: OpenAlex W4415256754; Crossref DOI record checked | T33: Recorded as arXiv preprint; DOI is the published ACM version. | U33: W4415256754 | V33: yes | W33: validation | X33: no
A34: S033 | B34: hrckova2025autonomation | C34: Hrckova, Andrea; Moro, Robert; Srba, Ivan; Simko, Jakub; Bielikova, Maria | D34: 2025 | E34: Autonomation, Not Automation: Activities and Needs of European Fact-checkers as a Basis for Designing Human-centered AI Systems | F34: ACM Journal on Responsible Computing | G34: Journal article | H34: 10.1145/3764592 | I34: Social media analysis | J34: Class 3 - Hybrid Human-AI Annotation and Verification | L34: 3.4 | M34: Opinion Detection and Modeling (C3) | N34: C3 | O34: Table C3 | P34: 3.4 Opinion Detection and Modeling; Appendix A.1 | Q34: Core | S34: OpenAlex W4414032582; Crossref DOI record checked | U34: W4414032582 | V34: yes | W34: validation | X34: no
A35: S034 | B35: cui2025toward | C35: Cui, Zikun; Huang, Tianyi; Chiang, Chia-En; Du, Cuiqianhe | D35: 2025 | E35: Toward Verifiable Misinformation Detection: A Multi-Tool LLM Agent Framework | F35: arXiv preprint arXiv:2508.03092 | G35: Preprint / working paper | H35: 10.1145/3766918.3766948 | I35: Social media analysis | J35: Class 3 - Hybrid Human-AI Annotation and Verification | L35: 3.4 | M35: Opinion Detection and Modeling (C3) | N35: C3 | O35: Table C3 | P35: 3.4 Opinion Detection and Modeling; Appendix A.1 | Q35: Core | S35: OpenAlex W4415736465; Crossref DOI record checked | T35: Recorded as arXiv preprint; DOI is the published ACM version. | U35: W4415736465 | V35: yes | W35: validation | X35: yes
A36: S035 | B36: lee2025countering | C36: Lee, Tuan-He; Fussell, Susan R | D36: 2025 | E36: Countering misinformation in private messaging groups: Insights from a fact-checking chatbot | F36: Proceedings of the ACM on human-computer interaction | G36: Journal article | H36: 10.1145/3701189 | I36: Social media analysis | J36: Class 3 - Hybrid Human-AI Annotation and Verification | L36: 3.4 | M36: Opinion Detection and Modeling (C3) | N36: C3 | O36: Table C3 | P36: 3.4 Opinion Detection and Modeling; Appendix A.1 | Q36: Core | S36: OpenAlex W4406258040; Crossref DOI record checked | U36: W4406258040 | V36: yes | W36: development
A37: S036 | B37: nobre2022hierarchical | C37: Nobre, Gabriel Peres; Ferreira, Carlos HG; Almeida, Jussara M | D37: 2022 | E37: A hierarchical network-oriented analysis of user participation in misinformation spread on WhatsApp | F37: Information Processing & Management | G37: Journal article | H37: 10.1016/j.ipm.2021.102757 | I37: Social media analysis | J37: Class 4 - Network Structure and Propagation Analysis | L37: 3.4 | M37: Opinion Detection and Modeling (C4) | N37: C4 | O37: Table C4 | P37: 3.4 Opinion Detection and Modeling; 4.1.3 Event-Level Descriptors; Appendix A.1 | Q37: Core | S37: OpenAlex W3203440807; Crossref DOI record checked | U37: W3203440807 | V37: yes | W37: validation | X37: yes
A38: S037 | B38: resende2019analyzing | C38: Resende, Gustavo; Melo, Philipe; CS Reis, Julio; Vasconcelos, Marisa; Almeida, Jussara M; Benevenuto, Fabrício | D38: 2019 | E38: Analyzing textual (mis) information shared in WhatsApp groups | F38: Proceedings of the 10th ACM Conference on Web Science | G38: Conference paper | H38: 10.1145/3292522.3326029 | I38: Social media analysis | J38: Class 4 - Network Structure and Propagation Analysis | L38: 3.4 | M38: Opinion Detection and Modeling (C4) | N38: C4 | O38: Table C4 | P38: 3.4 Opinion Detection and Modeling; 4.1.3 Event-Level Descriptors; Appendix A.1 | Q38: Core | S38: OpenAlex W2954093511; Crossref DOI record checked | U38: W2954093511 | V38: no
A39: S038 | B39: chen2022social | C39: Chen, Long; Chen, Jianguo; Xia, Chunhe | D39: 2022 | E39: Social network behavior and public opinion manipulation | F39: Journal of Information Security and Applications | G39: Journal article | H39: 10.1016/j.jisa.2021.103060 | I39: Social media analysis | J39: Class 4 - Network Structure and Propagation Analysis | L39: 3.4 | M39: Opinion Detection and Modeling (C4) | N39: C4 | O39: Table C4 | P39: 3.4 Opinion Detection and Modeling; Appendix A.1 | Q39: Core | S39: OpenAlex W4200463617; Crossref DOI record checked | U39: W4200463617 | V39: yes | W39: validation | X39: yes
A40: S039 | B40: loru2026compression | C40: Loru, Edoardo; Di Marco, Niccolò; Cinelli, Matteo; Quattrociocchi, Walter | D40: 2026 | E40: A Compression-Based Approach to Detecting Automated and Coordinated Behavior on Social Media | F40: ACM Transactions on Knowledge Discovery from Data | G40: Journal article | H40: 10.1145/3778356 | I40: Social media analysis | J40: Class 4 - Network Structure and Propagation Analysis | L40: 3.4 | M40: Opinion Detection and Modeling (C4) | N40: C4 | O40: Table C4 | P40: 3.4 Opinion Detection and Modeling; Appendix A.1 | Q40: Core | S40: OpenAlex W4416841974; Crossref DOI record checked | U40: W4416841974 | V40: yes | W40: development
...

Sheet not_in_corpus
A1: bibkey | B1: authors | C1: year | D1: title | E1: publication_type | F1: doi | G1: cited_in_section | H1: reason not in corpus
A2: kumar2018false | B2: Kumar, Srijan; Shah, Neil | C2: 2018 | D2: False information on web and social media: A survey | E2: Preprint / working paper | F2: 10.48550/arXiv.1804.08559 | G2: 1.1 | H2: Background and motivation (information ecosystem). Cited outside the sections counted in the PRISMA categories.
A3: armstrong2019organized | B3: Armstrong, Jeremy | C3: 2019 | D3: Organized chaos: manipuli, socii, and the Roman army c. 300 | E3: Book chapter | F3: 10.4324/9781351063500-5 | G3: 1.1 | H3: Historical motivation; possible citation-claim mismatch (chapter title concerns Roman army organisation). Cited outside the sections counted in the PRISMA categories.
A4: nam2025detecting | B4: Nam, D; Skillicorn, David B | C4: 2025 | D4: Detecting Pump &Dump stock market manipulation from online forums | E4: Journal article | F4: 10.1007/s42521-024-00121-4 | G4: 1.2 | H4: Background (algorithmic amplification). Cited outside the sections counted in the PRISMA categories.
A5: silva2025guidelines | B5: Silva, Marcus VS; dos Santos, Luiz FC; Soares, Michel S; Rocha, Fabio Gomes | C5: 2025 | D5: Guidelines for the Application of Event Driven Architecture in Micro Services with High Volume of Data | E5: Conference paper | F5: 10.5220/0013348600003929 | G5: 1.2 | H5: Software-engineering motivation. Cited outside the sections counted in the PRISMA categories.
A6: nazir2024architecting | B6: Nazir, Roger; Bucaioni, Alessio; Pelliccione, Patrizio | C6: 2024 | D6: Architecting ML-enabled systems: Challenges, best practices, and design decisions | E6: Journal article | F6: 10.1016/j.jss.2023.111860 | G6: 1.2 | H6: Software-engineering motivation. Cited outside the sections counted in the PRISMA categories.
A7: rahman2025secureai | B7: Abdur Rahman; Md. Badiuzzaman Biplob | C7: 2025 | D7: SecureAI-Flow: A Security-Oriented CI/CD Framework for AI Software | E7: Preprint / working paper | F7: 10.20944/preprints202506.0035.v1 | G7: 1.2 | H7: Software-engineering motivation. Cited outside the sections counted in the PRISMA categories.
A8: chen2025year | B8: Chen, Yisong; Zhao, Chuqing; Xu, Yixin; Nie, Chuanhao | C8: 2025 | D8: Year-over-year developments in financial fraud detection via deep learning: A systematic literature review | E8: Preprint / working paper | F8: 10.48550/arXiv.2502.00201 | G8: 1.2 | H8: Motivation (experimental prototypes). Cited outside the sections counted in the PRISMA categories.
A9: Cortis2020SocialOpinionMining | B9: Cortis, Keith; Davis, Brian | C9: 2020 | D9: Over a decade of social opinion mining: a systematic review | E9: Journal article | F9: 10.1007/s10462-020-09864-2 | G9: 1.4 | H9: Prior survey used to position the review. Cited outside the sections counted in the PRISMA categories.
A10: Reveilhac2022SocialMediaSurveys | B10: Reveilhac, Maud; Steinmetz, Stephanie; Morselli, Davide | C10: 2022 | D10: A systematic literature review of how and whether social media data can complement traditional survey data to study public opinion | E10: Journal article | F10: 10.1007/s11042-022-12121-3 | G10: 1.4 | H10: Prior survey used to position the review. Cited outside the sections counted in the PRISMA categories.
A11: Abkenar2020BigDataSocialMedia | B11: Bazzaz Abkenar, Sepideh; Kashani, Mohammad Hossein; Mahdipour, Ebrahim; Jameii, Seyed Mohammad | C11: 2020 | D11: Big data analytics meets social media: A systematic review of techniques, open issues, and future directions | E11: Journal article | F11: 10.1016/j.tele.2020.101517 | G11: 1.4 | H11: Prior survey used to position the review. Cited outside the sections counted in the PRISMA categories.
A12: Rahman2022SystematicReviewBigDataSocialMedia | B12: Rahman, Md. Saifur; Reza, Hassan | C12: 2022 | D12: A Systematic Review Towards Big Data Analytics in Social Media | E12: Journal article | F12: 10.26599/BDMA.2022.9020019 | G12: 1.4 | H12: Prior survey used to position the review. Cited outside the sections counted in the PRISMA categories.
A13: Long2025SocialMediaCapitalMarkets | B13: Long, Wen; Guo, Man | C13: 2025 | D13: Social media and capital markets: an interdisciplinary bibliometric analysis | E13: Journal article | F13: 10.1186/s40854-024-00731-2 | G13: 1.4 | H13: Prior survey used to position the review. Cited outside the sections counted in the PRISMA categories.
... A18: hinderks2020slr | B18: Hinderks, Andreas; Mayo, Francisco José Domínguez; Thomaschewski, Jörg; Escalona, María José | C18: 2020 | D18: An SLR-Tool: Search process in practice: A tool to conduct and manage systematic literature review (SLR) | E18: Conference paper | F18: 10.1145/3377812.3382137 | G18: 2 | H18: SLR methodology guideline. Cited outside the sections counted in the PRISMA categories.
A19: stapic2012performing | B19: Stapic, Zlatko; López, Eva García; Cabot, Antonio García; de Marcos Ortega, Luis; Strahonja, Vjeran | C19: 2012 | D19: Performing systematic literature review in software engineering | E19: Conference paper | G19: 2 | H19: SLR methodology guideline. Cited outside the sections counted in the PRISMA categories.
A20: page2021prisma | B20: Page, Matthew J; McKenzie, Joanne E; Bossuyt, Patrick M; Boutron, Isabelle; Hoffmann, Tammy C; Mulrow, Cynthia D; Shamseer, Larissa; Tetzlaff, Jennifer M; Akl, Elie A; Brennan, Sue E; et al. | C20: 2021 | D20: The PRISMA 2020 statement: An updated guideline for reporting systematic reviews | E20: Journal article | F20: 10.1136/bmj.n71 | G20: 2.2 | H20: PRISMA 2020 reporting guideline. Cited outside the sections counted in the PRISMA categories.
A21: hausner2012routine | B21: Hausner, Elke; Waffenschmidt, Siw; Kaiser, Thomas; Simon, Michael | C21: 2012 | D21: Routine development of objectively derived search strategies | E21: Journal article | F21: 10.1186/2046-4053-1-19 | G21: 2 (Reproducibility of the Review) | H21: Method for objectively derived search strategies (known-item retrieval check); cited in the revision. Cited outside the sections counted in the PRISMA categories.

Sheet codebook
A1: column | B1: label | C1: definition
A2: study_id | C2: Sequential identifier in manuscript order (S001-S126).
A3: bibkey | C3: Citation key exactly as used in the manuscript and surveybib.bib.
A4: publication_type | B4: Journal article / Conference paper / Book / Book chapter / Preprint / working paper | C4: Taken from the BibTeX entry type and venue field, as used for the corpus-composition table.
A5: theme | B5: Social media analysis / Financial market events / Cross-Domain Events and Causality | C5: The three groups of the PRISMA flow diagram ("Included studies categorized by conceptual theme").
A6: prisma_box | B6: 17 categories | C6: The category box of the PRISMA diagram in which the study is counted. Each study is counted once, in the first section where it is analysed.
A7: xref_to | C7: Further PRISMA category in which the study is also analysed. These are the "overlapping studies" shown in the diagram (2 in Financial signals, 1 in Cross-Domain Challenges, 5 in Causal Identification).
A8: section_no / section | C8: Manuscript section that corresponds to the PRISMA category.
A9: method_class | B9: C1-C6, F1-F5 | C9: Methodological class; assigned only where the study is listed in an appendix table.
A10: cited_in | C10: All manuscript sections in which the study is cited.
A11: study_role | B11: Core | C11: Findings or contributions analysed to characterise the state of research.
A12: study_role | B12: Foundational | C12: Cited as the origin or standard reference of a definition, model or statistical method; included by the rule in Section 2.2 on foundational works.
A13: revision_status | B13: restored to text in revision | C13: Study belonged to the corpus counted in the PRISMA diagram; its citation had been lost from the text during revision and was restored.
A14: metadata_check | C14: Result of the metadata check of 19 October 2026: OpenAlex work ID, and whether the DOI record was checked in Crossref. Bibliographic data are taken from surveybib_corrected.bib.
A15: note | C15: Correction applied to the .bib entry, or a remaining point to verify.
A16: openalex_id | C16: OpenAlex work identifier (https://openalex.org/<id>). Empty = not indexed in OpenAlex.
A17: in_search_window | B17: yes / no | C17: Publication year 2021-2026 (the database search window, Section 2.2). Only these studies enter the known-item retrieval check; older works are foundational works included through citation searching.
A18: validation_set | B18: development / validation | C18: Set of the known-item retrieval check (studies published 2021-2026 only; split at random within each PRISMA category, seed 20261019). Development titles were used to derive the query; validation studies were used only to evaluate it.
A19: retrieved_by_final_query | B19: yes / no / not indexed in OpenAlex | C19: Validation set only: whether the final query of the known-item retrieval check (sheet validation_result: term query with the date, document-type and subject-field restrictions) returned the study in OpenAlex on 20 October 2026. Empty for the development set, whose titles were used to build the query (development set: 42 of 44 retrieved).

Sheet class_definitions
A1: class | B1: name (manuscript heading) | C1: definition (quoted from the manuscript) | D1: manuscript section | E1: appendix table | F1: studies in register
A2: C1 | B2: Mathematical and System-Dynamics Modeling of Opinion Manipulation | C2: The first class approaches opinion manipulation as a dynamic process that can be described using formal mathematical models. In this line of work, the main objective is not to classify individual posts or claims, but to understand how opinions change over time, when instability emerges, and under which conditions misinformation becomes dominant or polarization intensifies. | D2: 3.4 Opinion Detection and Modeling | E2: Table C1 | F2: =COUNTIF(Data!$N$2:$N$127,A2) -> 6
A3: C2 | B3: Statistical Machine Learning and Deep Learning Content Detection | C3: The second class treats opinion manipulation primarily as a content detection problem. Here the central task is to determine whether a post, article, claim, or rumor is false, misleading, or otherwise suspicious by learning patterns from text and related contextual information. | D3: 3.4 Opinion Detection and Modeling | E3: Table C2 | F3: =COUNTIF(Data!$N$2:$N$127,A3) -> 8
A4: C3 | B4: Hybrid Human-AI Annotation and Verification | C4: The third class arises because manipulation is not always detectable by automatic classification. Context-sensitive claims and rhetorical devices frequently require human interpretation. | D4: 3.4 Opinion Detection and Modeling | E4: Table C3 | F4: =COUNTIF(Data!$N$2:$N$127,A4) -> 6
A5: C4 | B5: Network Structure and Propagation Analysis | C5: The fourth class of studies examines opinion manipulation via patterns of diffusion, community structures, and actor roles. In these studies, misinformation is no longer considered a characteristic of a given piece of text, but rather a phenomenon in terms of how it diffuses within a social group, who promotes it, and how network structures influence its persistence and spread. | D5: 3.4 Opinion Detection and Modeling | E5: Table C4 | F5: =COUNTIF(Data!$N$2:$N$127,A5) -> 8
A6: C5 | B6: Behavioral and Psychological Modeling | C6: The fifth class examines manipulation from the perspective of the user, rather than focusing on the message or the network. The main question is why some people are more vulnerable to misleading information, more likely to believe it, and more affected emotionally and behaviorally. | D6: 3.4 Opinion Detection and Modeling | E6: Table C5 | F6: =COUNTIF(Data!$N$2:$N$127,A6) -> 8
A7: C6 | B7: Intervention and Inoculation Strategies | C7: The sixth class brings the discussion from explanation to response. Instead of asking how manipulation works or why people are vulnerable, these studies test strategies intended to weaken manipulation, improve resistance, or redesign the environment in which misinformation spreads. | D7: 3.4 Opinion Detection and Modeling | E7: Table C6 | F7: =COUNTIF(Data!$N$2:$N$127,A7) -> 8
A8: F1 | B8: Classical event-study econometrics | C8: Classical event studies evaluate whether an externally identified event is associated with abnormal security returns. | D8: 3.6 Methodological Approaches in Financial Event Research | E8: Table F1 | F8: =COUNTIF(Data!$N$2:$N$127,A8) -> 8
A9: F2 | B9: Volatility, risk, and structural change | C9: Financial events may also appear as changes in volatility or in the parameters governing the return-generating process rather than as directional changes in mean returns. | D9: 3.6 Methodological Approaches in Financial Event Research | E9: Table F2 | F9: =COUNTIF(Data!$N$2:$N$127,A9) -> 7
A10: F3 | B10: High-frequency and intraday market response | C10: High-frequency approaches reduce the observation window from days to minutes, seconds, or transaction time, thereby allowing more precise analysis of how markets react around information arrivals. | D10: 3.6 Methodological Approaches in Financial Event Research | E10: Table F3 | F10: =COUNTIF(Data!$N$2:$N$127,A10) -> 9
A11: F4 | B11: Textual and attention-augmented asset pricing | C11: A fourth group converts information itself into measurable financial signals. | D11: 3.6 Methodological Approaches in Financial Event Research | E11: Table F4 | F11: =COUNTIF(Data!$N$2:$N$127,A11) -> 8
A12: F5 | B12: Market manipulation and abusive trading detection | C12: The final group concerns information or trading activity intentionally designed to influence market behavior. | D12: 3.6 Methodological Approaches in Financial Event Research | E12: Table F5 | F12: =COUNTIF(Data!$N$2:$N$127,A12) -> 8
E13: Total | F13: =SUM(F2:F12) -> 84
A15: Assignment: each of the 84 studies listed in the appendix tables is assigned to exactly one class (it appears in one appendix table). Studies were coded and classified by the first author according to their thematic focus and methodological characteristics, and the classifications were reviewed by the research supervisors; ambiguous cases were discussed jointly until agreement was reached (Section 2.2). The manuscript does not report an agreement statistic.
A16: The other 42 included studies (opinion and its manipulation, social-media and financial signals, cross-domain challenges, causal identification) are not assigned to a class (column method_class empty on Data).

Sheet Counts
A1: Publication type | B1: Reported (corpus-composition table) | C1: Register | D1: Difference
A2: Journal article | B2: 103 | C2: =COUNTIF(Data!$G$2:$G$127,A2) -> 103 | D2: =C2-B2 -> 0
A3: Conference paper | B3: 7 | C3: =COUNTIF(Data!$G$2:$G$127,A3) -> 7 | D3: =C3-B3 -> 0
A4: Book | B4: 3 | C4: =COUNTIF(Data!$G$2:$G$127,A4) -> 3 | D4: =C4-B4 -> 0
A5: Book chapter | B5: 2 | C5: =COUNTIF(Data!$G$2:$G$127,A5) -> 2 | D5: =C5-B5 -> 0
A6: Preprint / working paper | B6: 11 | C6: =COUNTIF(Data!$G$2:$G$127,A6) -> 11 | D6: =C6-B6 -> 0
A7: Total | B7: =SUM(B2:B6) -> 126 | C7: =SUM(C2:C6) -> 126 | D7: =SUM(D2:D6) -> 0
A9: Theme | B9: Reported (PRISMA diagram) | C9: Register | D9: Difference
A10: Social media analysis | B10: 59 | C10: =COUNTIF(Data!$I$2:$I$127,A10) -> 59 | D10: =C10-B10 -> 0
A11: Financial market events | B11: 40 | C11: =COUNTIF(Data!$I$2:$I$127,A11) -> 40 | D11: =C11-B11 -> 0
A12: Cross-Domain Events and Causality | B12: 27 | C12: =COUNTIF(Data!$I$2:$I$127,A12) -> 27 | D12: =C12-B12 -> 0
A13: Total | B13: =SUM(B10:B12) -> 126 | C13: =SUM(C10:C12) -> 126 | D13: =SUM(D10:D12) -> 0
A15: Study role | C15: Register
A16: Core | C16: =COUNTIF(Data!$Q$2:$Q$127,A16) -> 89
A17: Foundational | C17: =COUNTIF(Data!$Q$2:$Q$127,A17) -> 37
A19: Publication years (min / max) | B19: Reported: 1969-2026 | C19: =MIN(Data!$D$2:$D$127)&"-"&MAX(Data!$D$2:$D$127) -> 1969-2026
A21: OpenAlex (metadata check and retrieval check) | C21: Register
A22: Included studies published 2021-2026 (search window) | C22: =COUNTIF(Data!$V$2:$V$127,"yes") -> 82
A23: of which indexed in OpenAlex | C23: =COUNTIFS(Data!$V$2:$V$127,"yes",Data!$U$2:$U$127,"<>") -> 80
A24: Studies (of 126) indexed in OpenAlex (metadata check) | C24: =COUNTIF(Data!$U$2:$U$127,"<>") -> 122
A30: Blue = value reported in the manuscript; black = computed from the Data sheet.

Sheet PRISMA_check
A1: Theme | B1: PRISMA category | C1: Diagram: n | D1: Diagram: overlapping | E1: Register: counted here | F1: Register: overlapping | G1: Register: n | H1: Match
A2: Social media analysis | B2: Opinion in Social Networks | C2: 9 | D2: 0 | E2: =COUNTIF(Data!$J$2:$J$127,B2) -> 9 | F2: =SUMPRODUCT(--ISNUMBER(SEARCH(B2,Data!$K$2:$K$127))) -> 0 | G2: =E2+F2 -> 9 | H2: =IF(AND(G2=C2,F2=D2),"yes","NO") -> yes
A3: Social media analysis | B3: Opinion Manipulation: Definition and Typologies | C3: 6 | D3: 0 | E3: =COUNTIF(Data!$J$2:$J$127,B3) -> 6 | F3: =SUMPRODUCT(--ISNUMBER(SEARCH(B3,Data!$K$2:$K$127))) -> 0 | G3: =E3+F3 -> 6 | H3: =IF(AND(G3=C3,F3=D3),"yes","NO") -> yes
A4: Social media analysis | B4: Class 1 - Mathematical and System-Dynamics Modelling | C4: 6 | D4: 0 | E4: =COUNTIF(Data!$J$2:$J$127,B4) -> 6 | F4: =SUMPRODUCT(--ISNUMBER(SEARCH(B4,Data!$K$2:$K$127))) -> 0 | G4: =E4+F4 -> 6 | H4: =IF(AND(G4=C4,F4=D4),"yes","NO") -> yes
A5: Social media analysis | B5: Class 2 - Machine & Deep Learning Content Detection | C5: 8 | D5: 0 | E5: =COUNTIF(Data!$J$2:$J$127,B5) -> 8 | F5: =SUMPRODUCT(--ISNUMBER(SEARCH(B5,Data!$K$2:$K$127))) -> 0 | G5: =E5+F5 -> 8 | H5: =IF(AND(G5=C5,F5=D5),"yes","NO") -> yes
A6: Social media analysis | B6: Class 3 - Hybrid Human-AI Annotation and Verification | C6: 6 | D6: 0 | E6: =COUNTIF(Data!$J$2:$J$127,B6) -> 6 | F6: =SUMPRODUCT(--ISNUMBER(SEARCH(B6,Data!$K$2:$K$127))) -> 0 | G6: =E6+F6 -> 6 | H6: =IF(AND(G6=C6,F6=D6),"yes","NO") -> yes
A7: Social media analysis | B7: Class 4 - Network Structure and Propagation Analysis | C7: 8 | D7: 0 | E7: =COUNTIF(Data!$J$2:$J$127,B7) -> 8 | F7: =SUMPRODUCT(--ISNUMBER(SEARCH(B7,Data!$K$2:$K$127))) -> 0 | G7: =E7+F7 -> 8 | H7: =IF(AND(G7=C7,F7=D7),"yes","NO") -> yes
A8: Social media analysis | B8: Class 5 - Behavioural and Psychological Modelling | C8: 8 | D8: 0 | E8: =COUNTIF(Data!$J$2:$J$127,B8) -> 8 | F8: =SUMPRODUCT(--ISNUMBER(SEARCH(B8,Data!$K$2:$K$127))) -> 0 | G8: =E8+F8 -> 8 | H8: =IF(AND(G8=C8,F8=D8),"yes","NO") -> yes
A9: Social media analysis | B9: Class 6 - Intervention and Inoculation Strategies | C9: 8 | D9: 0 | E9: =COUNTIF(Data!$J$2:$J$127,B9) -> 8 | F9: =SUMPRODUCT(--ISNUMBER(SEARCH(B9,Data!$K$2:$K$127))) -> 0 | G9: =E9+F9 -> 8 | H9: =IF(AND(G9=C9,F9=D9),"yes","NO") -> yes
A10: Financial market events | B10: F1 - Classical event-study econometrics | C10: 8 | D10: 0 | E10: =COUNTIF(Data!$J$2:$J$127,B10) -> 8 | F10: =SUMPRODUCT(--ISNUMBER(SEARCH(B10,Data!$K$2:$K$127))) -> 0 | G10: =E10+F10 -> 8 | H10: =IF(AND(G10=C10,F10=D10),"yes","NO") -> yes
A11: Financial market events | B11: F2 - Volatility, risk, and structural change | C11: 7 | D11: 0 | E11: =COUNTIF(Data!$J$2:$J$127,B11) -> 7 | F11: =SUMPRODUCT(--ISNUMBER(SEARCH(B11,Data!$K$2:$K$127))) -> 0 | G11: =E11+F11 -> 7 | H11: =IF(AND(G11=C11,F11=D11),"yes","NO") -> yes
A12: Financial market events | B12: F3 - High-frequency and intraday market response | C12: 9 | D12: 0 | E12: =COUNTIF(Data!$J$2:$J$127,B12) -> 9 | F12: =SUMPRODUCT(--ISNUMBER(SEARCH(B12,Data!$K$2:$K$127))) -> 0 | G12: =E12+F12 -> 9 | H12: =IF(AND(G12=C12,F12=D12),"yes","NO") -> yes
A13: Financial market events | B13: F4 - Textual and attention-augmented asset pricing | C13: 8 | D13: 0 | E13: =COUNTIF(Data!$J$2:$J$127,B13) -> 8 | F13: =SUMPRODUCT(--ISNUMBER(SEARCH(B13,Data!$K$2:$K$127))) -> 0 | G13: =E13+F13 -> 8 | H13: =IF(AND(G13=C13,F13=D13),"yes","NO") -> yes
... A18: Cross-Domain Events and Causality | B18: Causal Identification | C18: 19 | D18: 5 | E18: =COUNTIF(Data!$J$2:$J$127,B18) -> 14 | F18: =SUMPRODUCT(--ISNUMBER(SEARCH(B18,Data!$K$2:$K$127))) -> 5 | G18: =E18+F18 -> 19 | H18: =IF(AND(G18=C18,F18=D18),"yes","NO") -> yes
B19: Total studies (each counted once) | C19: 126 | E19: =SUM(E2:E18) -> 126 | H19: =IF(E19=C19,"yes","NO") -> yes

Sheet search_concepts_table2
A1: concept | B1: keywords and synonyms | C1: representative Boolean string (as reported) | D1: records (as reported)
A2: Social Media Manipulation | B2: misinformation, disinformation, fake news, propaganda, opinion manipulation, influence operations | C2: ("social media" OR "online social networks") AND (misinformation OR disinformation OR "fake news" OR propaganda OR "opinion manipulation") | D2: 1667
A3: Opinion Dynamics in Networks | B3: opinion dynamics, social influence, information diffusion, consensus formation, bounded confidence | C3: ("opinion dynamics" OR "information diffusion" OR "social influence") AND ("social networks" OR "online social networks") | D3: 762
A4: Event Detection in Social Media | B4: event detection, burst detection, topic detection, social media events, event extraction | C4: ("event detection" OR "bursty events" OR "event extraction") AND ("social media" OR "online social networks") | D4: 172
A5: Fake News and Propaganda Detection | B5: fake news detection, propaganda detection, rumor detection, misinformation classification | C5: ("fake news detection" OR "propaganda detection" OR "rumor detection") AND ("social media" OR "online platforms") | D5: 382
A6: Financial Events and Market Responses | B6: event studies, abnormal returns, volatility, structural changes, high-frequency market responses | C6: ("event study" OR "financial event" OR "market event" OR "information event") AND ("abnormal return" OR volatility OR "structural break" OR "market reaction") | D6: 1066
A7: Social Media and Financial Markets | B7: investor sentiment, investor attention, misinformation, market manipulation, pump and dump, market reactions | C7: ("social media" OR Twitter OR Reddit OR Telegram) AND ("stock market" OR "financial market" OR cryptocurrency) AND ("market reaction" OR "market impact" OR "price impact" OR "return predictability" OR "market manipulation") | D7: 530
C8: Total | D8: =SUM(D2:D7) -> 4579
A10: Source: search-concepts table (tab:search_concepts), Section 2.2. They are not the query of the known-item retrieval check.

Sheet search_protocol
A1: # Known-item retrieval check: protocol
A3: Retrospective check of whether the included studies of the review can be retrieved in OpenAlex by a
A4: title query that is derived by fixed rules from part of the included studies and tested on the others
A5: (objective approach of Hausner E, Waffenschmidt S, Kaiser T, Simon M. Routine development of
A6: objectively derived search strategies. Systematic Reviews 2012;1:19. doi:10.1186/2046-4053-1-19).
A8: This experiment measures known-item retrieval within the previously selected corpus. Because both the
A9: development and validation samples originate from that corpus, the results are conditional on the
A10: original study-selection process and cannot establish the completeness, representativeness, or
A11: sensitivity of the original systematic search. The check does not reproduce the original search of
A12: the review (Section 2.2, Table 2 and the PRISMA diagram of the manuscript). Section 8 records when each
A13: rule was fixed.
A15: ## 1. Population and split (split_corpus.py)
... A145: selection bias.

Sheet validation_result
A1: item | B1: value
A2: protocol | B2: search_protocol (PROTOCOL.md). Term query, threshold, date and document-type restrictions fixed on 19 October 2026 before any count; subject-field restriction added on 20 October 2026 after earlier runs; a language filter was tested and dropped (sheet protocol_history).
A3: what the check measures | B3: Known-item retrieval within the previously selected corpus. Because both the development and validation samples originate from that corpus, the results are conditional on the original study selection and cannot establish the completeness, representativeness or sensitivity of the original systematic search.
A4: database | B4: OpenAlex, title search (title.search). Term query frozen on 19 October 2026; final run on 20 October 2026 (run_final.py).
A5: date restriction | B5: from_publication_date:2020-01-01,to_publication_date:2026-12-31 - one year before the 2021-2026 window of the included studies, because OpenAlex dates some works by their first online or preprint version (among the 82 studies, arnold2022attention, published in 2022, is dated 2020 in OpenAlex; no validation study is dated before 2021).
A6: document-type restriction | B6: type:!dissertation,type:!dataset,type:!paratext,type:!editorial,type:!letter,type:!erratum,type:!peer-review,type:!retraction - all other types (journal articles, conference papers, books, book chapters, preprints) are kept.
A7: subject-field restriction | B7: Not an eligibility criterion; used to reduce the number of records. OpenAlex field of the primary topic, kept if it is the field of at least one development study: Social Sciences (23 development studies); Economics, Econometrics and Finance (15 development studies); Computer Science (3 development studies); Physics and Astronomy (2 development studies); Decision Sciences (1 development studies). Chosen after the fields of the validation studies had been inspected, so not independently validated.
A8: language restriction | B8: none. OpenAlex leaves some works without a language, and a language filter would exclude two included studies (cui2025toward, goldsmith2025causal); the English-language criterion is applied at screening.
A9: N (works with the date and type restrictions; used for the ratios) | B9: 71,319,636
A10: threshold R (chosen on the development set) | B10: 100
A11: frozen term query (27 terms) | B11: causal OR chamber OR chatbot OR cryptocurrency OR disinformation OR echo OR "event studies" OR fake OR "financial market" OR garch OR hawkes OR "influence operations" OR investor OR manipulation OR misinformation OR news OR "online social networks" OR opinion OR propaganda OR "pump and dump" OR reddit OR rumor OR sentiment OR "social networks" OR stock OR "structural break" OR twitter
A12: term query SHA-256 | B12: 51377ba9737a1b12a8a0b8878bb0c5a27f32e47ad78dd6255a59cf54fb06a7f6 (documents the exact query run; it does not by itself show that the configuration was chosen independently of the validation results)
A13: records returned | B13: 311,556 (without the subject-field restriction on the same day: 528,902; removed by the restriction: 217,346, 41.1%)
A14: records not tagged as English (descriptive) | B14: 63,578 (20.4%; another language or no language assigned)
A15: validation set, all (primary outcome) | B15: 29/38 = 76.3% (95% CI 60.8%-87.0%)
A16: validation set, indexed in OpenAlex | B16: 29/36 = 80.6% (95% CI 65.0%-90.2%)
A17: development set | B17: 42/44 = 95.5% (95% CI 84.9%-98.7%)
A18: validation studies indexed in OpenAlex but not retrieved (7) | B18: hrckova2025autonomation; liu2024exploring; smith2024unraveling; su2025emotionally; yang2025price; bradley2024place; roy2024unveiling
A19: validation studies not indexed in OpenAlex (2) | B19: cayuela2025influence; kumarsocial
A20: interpretation | B20: The subject-field restriction did not remove any of the known included studies retrieved by the original query: the original pre-specified configuration retrieved the same validation studies (sheet protocol_history). The check does not show that the records removed by the restriction contain no other relevant studies, and it cannot be used as evidence of the absence of selection bias.
A21: method note | B21: Offline matching of the development titles was used exclusively for threshold selection; all retrieval outcomes were determined from the actual OpenAlex search results.
A22: field check | B22: All 36 indexed validation studies have their primary topic in one of the fields kept (sheet openalex_fields).
A24: Threshold selection on the development set (offline title match)
A25: R | B25: terms in query | C25: development titles matched
A26: 10 | B26: 48 | C26: 1
A27: 20 | B27: 44 | C27: 1
A28: 50 | B28: 36 | C28: 0.977
A29: 100 | B29: 27 | C29: 0.955
A30: 200 | B30: 25 | C30: 0.841
A31: 500 | B31: 21 | C31: 0.727
A32: 1000 | B32: 16 | C32: 0.614
A34: Validation set: per-study result
A35: bibkey | B35: PRISMA category | C35: OpenAlex ID | D35: OpenAlex field | E35: retrieved
A36: assaad2022survey | B36: Causal Identification | C36: W4214698730 | D36: Computer Science | E36: yes
A37: ghazouani2025virtual | B37: Causal Identification | C37: W4413466225 | D37: Economics, Econometrics and Finance | E37: yes
A38: sadeghi2025causal | B38: Causal Identification | C38: W4404439782 | D38: Computer Science | E38: yes
A39: bhalla2025local | B39: Class 1 - Mathematical and System-Dynamics Modelling | C39: W3216173699 | D39: Physics and Astronomy | E39: yes
A40: evangelatos2025modeling | B40: Class 1 - Mathematical and System-Dynamics Modelling | C40: W4412593918 | D40: Social Sciences | E40: yes
